<?xml version="1.0"?>
<robot xmlns:xacro="http://ros.org/wiki/xacro" name="robotiq_gripper">

  <!--
    Based on the URDF file by Cristian C Beltran-Hernandez
  -->  

  <!-- <xacro:include filename="$(find robotiq_description)/urdf/materials.xacro" /> -->
  <material name="Grey">
    <color rgba="0.5 0.5 0.9 1.0"/>
  </material>

  <material name="DarkGrey">
    <color rgba="0.04 0.04 0.04 1.0"/>
  </material>

  <xacro:macro name="robotiq_gripper" params="
    name
    prefix
    parent
    *origin
    sim_ignition:=false
    sim_isaac:=false
    isaac_joint_commands:=/isaac_joint_commands
    isaac_joint_states:=/isaac_joint_states
    use_fake_hardware:=false
    fake_sensor_commands:=false
    include_ros2_control:=true
    com_port:=/dev/ttyUSB0">

    <!-- ros2 control include -->
    <xacro:include filename="$(find robotiq_description)/urdf/2f_hande.ros2_control.xacro" />
    <!-- if we are simulating or directly communicating with the gripper we need a ros2 control instance -->
    <xacro:if value="${include_ros2_control}">
        <xacro:robotiq_gripper_ros2_control
            name="${name}" prefix="${prefix}"
            sim_ignition="${sim_ignition}"
            sim_isaac="${sim_isaac}"
            isaac_joint_commands="${isaac_joint_commands}"
            isaac_joint_states="${isaac_joint_states}"
            use_fake_hardware="${use_fake_hardware}"
            fake_sensor_commands="${fake_sensor_commands}"
            com_port="${com_port}"/>
    </xacro:if>

    <!-- Robotiq Coupler -->
    <!--  + Height added by the coupler: 13.9mm -->
    <!--  + Reference frame: at the middle (6.95mm) -->
    <!-- <joint name="${prefix}robotiq_coupler_joint" type="fixed">
      <origin xyz="0 0 0.00695" rpy="0 0 ${-pi/2.0}" />
      <parent link="${parent}"/>
      <child link="${prefix}robotiq_coupler"/>
    </joint>

    <link name="${prefix}robotiq_coupler">
      <inertial>
        <mass value="0.168" />
        <inertia 
          ixx="6.17674E-05" ixy="0.0" ixz="0.0" 
          iyy="6.17674E-05" iyz="0.0" 
          izz="1.18125E-04"
        />
      </inertial>

      <collision>
        <geometry>
          <cylinder length="0.0139" radius="0.0375"/>
        </geometry>
      </collision>

      <visual>
        <geometry>
          <mesh filename="file://$(find robotiq_description)/meshes/visual/hande/coupler.dae" />
        </geometry>
        <material name="DarkGrey" />
      </visual>
    </link> -->


    <joint name="${prefix}hande_base_joint" type="fixed">
      <!-- <origin rpy="0 0 0" xyz="0 0 0.055"/> -->
      <parent link="${parent}"/>
      <child link="${prefix}hande_base_link"/>
      <xacro:insert_block name="origin" />
    </joint>

    <link name="${prefix}hande_base_link">
      <inertial>
        <mass value="0.86387"/>
        <inertia 
          ixx="0.001" ixy="0.0" ixz="0.0" 
          iyy="0.001" iyz="0.0" 
          izz="0.0006"
        />  
      </inertial>

      <collision>
        <geometry>
          <cylinder length="0.0988" radius="0.0375"/>
        </geometry>
      </collision>

      <visual>
        <origin rpy="0 -1.570796 -1.570796" xyz="0 0 -0.0016"/>
        <geometry>
          <mesh filename="file://$(find robotiq_description)/meshes/visual/hande/hande.dae" scale="1.0 1.0 1.0"/>
        </geometry>
        <material name="DarkGrey"/>
      </visual>
    </link>


    <joint name="${prefix}hande_left_finger_joint" type="prismatic">
      <origin rpy="0 0 0" xyz="0 -0.025 0.0345"/>
      <parent link="${prefix}hande_base_link"/>
      <child link="${prefix}hande_left_finger"/>
      <axis xyz="0 1 0"/>
      <limit effort="130" lower="0" upper="0.025" velocity="0.15"/>
    </joint>

    <link name="${prefix}hande_left_finger">
      <inertial>
        <origin rpy="0 0 0" xyz="0 0 0"/>
        <mass value="0.03804"/>
        <inertia
          ixx="1E-9" ixy="0.0" ixz="0.0" 
          iyy="1E-9" iyz="0.0" 
          izz="1E-9"
        />
      </inertial>

      <collision>
        <origin rpy="0 0 3.1415926" xyz="0 0 0"/>
        <geometry>
          <mesh filename="file://$(find robotiq_description)/meshes/collision/hande/finger.dae" scale="1.0 1.0 1.0"/>
        </geometry>
      </collision>

      <visual>
        <origin rpy="1.570796 0 3.1415926" xyz="0 0 0"/>
        <geometry>
          <mesh filename="file://$(find robotiq_description)/meshes/visual/hande/finger.dae" scale="1.0 1.0 1.0"/>
        </geometry>
        <material name="Grey"/>
      </visual>
    </link>


    <joint name="${prefix}hande_right_finger_joint" type="prismatic">
      <origin rpy="0 0 0" xyz="0 0.025 0.0345"/>
      <parent link="${prefix}hande_base_link"/>
      <child link="${prefix}hande_right_finger"/>
      <axis xyz="0 -1 0"/>
      <limit effort="130" lower="0" upper="0.025" velocity="0.15"/>
      <mimic joint="${prefix}hande_left_finger_joint" multiplier="1" offset="0"/>
    </joint>

    <link name="${prefix}hande_right_finger">
      <inertial>
        <origin rpy="0 0 0" xyz="0 0 0"/>
        <mass value="0.03804"/>
        <inertia
          ixx="1E-9" ixy="0.0" ixz="0.0" 
          iyy="1E-9" iyz="0.0" 
          izz="1E-9"
        />
      </inertial>

      <collision>
        <origin rpy="0 0 0" xyz="0 0 0"/>
        <geometry>
          <mesh filename="file://$(find robotiq_description)/meshes/collision/hande/finger.dae" scale="1.0 1.0 1.0"/>
        </geometry>
      </collision>

      <visual>
        <origin rpy="1.570796 0 0" xyz="0 0 0"/>
        <geometry>
          <mesh filename="file://$(find robotiq_description)/meshes/visual/hande/finger.dae" scale="1.0 1.0 1.0"/>
        </geometry>
        <material name="Grey" />
      </visual>
    </link>


    <joint name="${prefix}robotiq_hande_end_joint" type="fixed">
      <origin rpy="0 0 0" xyz="0 0 0.095"/>
      <parent link="${prefix}hande_base_link"/>
      <child link="${prefix}hande_end"/>
    </joint>

    <link name="${prefix}hande_end" />

  </xacro:macro>
</robot>
